<?xml version="1.0" encoding="utf-8"?>
  <sdf version="1.6">
    <model name="bug">
      <!-- <joint name='world_weld' type='fixed'>
        <pose frame=''>0 0 0 0 0 0</pose>
        <parent>world</parent>
        <child>base</child>
      </joint> -->
      <link name="base">
        <pose frame="">0 0 0 0 0 0</pose>
      </link>
      <!-- =============== Gantry ============== -->
      <joint name="base_weld" type="fixed">
        <pose frame="">0 0 0 0 0 0</pose>
        <child>link_0</child>
        <parent>base</parent>
      </joint>
      <!-- Gantry Link 0 (Y-axis "left" rail) -->
      <link name="link_0">
        <pose frame="">0 0 0 0 0 0</pose>
        <inertial>
          <pose frame="">0 -1.25 0 0 0 0</pose>
          <mass>2.7025</mass>
          <inertia>
            <ixx>0.0171</ixx>
            <ixy>0</ixy>
            <ixz>0</ixz>
            <iyy>0.0163</iyy>
            <iyz>0</iyz>
            <izz>0.006</izz>
          </inertia>
        </inertial>
        <gravity>1</gravity>
        <velocity_decay/>
        <self_collide>0</self_collide>
        <visual name="visual">
          <pose frame="">0 -1.25 0 0 0 0</pose>
          <geometry>
            <box>
              <size>0.15 2.5 0.14</size>
            </box>
          </geometry>
          <material>
            <!-- Clark+Kensington Stainless Steel / 37B-4 / #98acc3 Hex Color Code -->
            <diffuse>0.59 0.67 0.76</diffuse>
          </material>
        </visual>
      </link>
      <joint name="joint_1" type="prismatic">
        <parent>link_0</parent>
        <child>link_1</child>
        <axis>
          <xyz>0 -1 0</xyz>
          <limit>
            <lower>-1.25</lower>
            <upper>1.25</upper>
            <effort>300</effort>
            <velocity>10</velocity>
          </limit>
          <dynamics>
            <damping>0.0</damping>
            <friction>0</friction>
            <spring_reference>0</spring_reference>
            <spring_stiffness>0</spring_stiffness>
          </dynamics>
          <use_parent_model_frame>1</use_parent_model_frame>
        </axis>
      </joint>
      <!-- Gantry Link 1 (X-axis "forward" rail) -->
      <link name="link_1">
        <pose frame="">0 0 0 0 0 0</pose>
        <inertial>
          <pose frame="">1.5 0 0 0 0 0</pose>
          <mass>2.7025</mass>
          <inertia>
            <ixx>0.0171</ixx>
            <ixy>0</ixy>
            <ixz>0</ixz>
            <iyy>0.0163</iyy>
            <iyz>0</iyz>
            <izz>0.006</izz>
          </inertia>
        </inertial>
        <gravity>1</gravity>
        <velocity_decay/>
        <self_collide>0</self_collide>
        <visual name="visual">
          <pose frame="">1.5 0 0 0 0 0</pose>
          <geometry>
            <box>
              <size>3.0 0.1125 0.126</size>
            </box>
          </geometry>
          <material>
            <!-- Clark+Kensington Stainless Steel / 37B-4 / #98acc3 Hex Color Code -->
            <diffuse>0.59 0.67 0.76</diffuse>
          </material>
        </visual>
      </link>
      <joint name="joint_2" type="prismatic">
        <parent>link_1</parent>
        <child>link_2</child>
        <axis>
          <xyz>1 0 0</xyz>
          <limit>
            <lower>-1.5</lower>
            <upper>1.5</upper>
            <effort>300</effort>
            <velocity>10</velocity>
          </limit>
          <dynamics>
            <damping>0.0</damping>
            <friction>0</friction>
            <spring_reference>0</spring_reference>
            <spring_stiffness>0</spring_stiffness>
          </dynamics>
          <use_parent_model_frame>1</use_parent_model_frame>
        </axis>
      </joint>
      <!-- Gantry Link 2 (z-axis "yaw" rotation) -->
      <link name="link_2">
        <pose frame="">0 0 0 0 0 0</pose>
        <inertial>
          <pose frame="">0 0 0 0 0 0</pose>
          <mass>2.7025</mass>
          <inertia>
            <ixx>0.0171</ixx>
            <ixy>0</ixy>
            <ixz>0</ixz>
            <iyy>0.0163</iyy>
            <iyz>0</iyz>
            <izz>0.006</izz>
          </inertia>
        </inertial>
        <gravity>1</gravity>
        <velocity_decay/>
        <self_collide>0</self_collide>
        <visual name="visual">
          <pose frame="">0 0 0.0616 0 0 0</pose>
          <geometry>
            <cylinder>
              <radius>0.05</radius>
              <length>0.672</length>
            </cylinder>
          </geometry>
          <material>
            <!-- Lascaux Carbon black / 181 / #1a3640 Hex Color Code -->
            <diffuse>0.2 0.21 0.25</diffuse>
          </material>
        </visual>
        <visual name="visual_truss">
          <pose frame="">0 0 0.0616 0 0.785398163397 0</pose>
          <geometry>
            <box>
              <size>0.48 0.05 0.448</size>
            </box>
          </geometry>
          <material>
            <!-- Clark+Kensington Stainless Steel / 37B-4 / #98acc3 Hex Color Code -->
            <diffuse>0.59 0.67 0.76</diffuse>
          </material>
        </visual>
      </link>
      <joint name="joint_3" type="revolute">
        <parent>link_2</parent>
        <child>link_3</child>
        <axis>
          <xyz>0 0 1</xyz>
          <limit>
            <lower>-6.28318530718</lower>
            <upper>6.28318530718</upper>
            <effort>300</effort>
            <velocity>10</velocity>
          </limit>
          <dynamics>
            <damping>0.0</damping>
            <friction>0</friction>
            <spring_reference>0</spring_reference>
            <spring_stiffness>0</spring_stiffness>
          </dynamics>
          <use_parent_model_frame>1</use_parent_model_frame>
        </axis>
      </joint>
      <!-- Gantry Link 3 (Z-axis "up" rail) -->
      <link name="link_3">
        <pose frame="">0 0 0 0 0 0</pose>
        <inertial>
          <pose frame="">0 0 1.4 0 0 0</pose>
          <mass>2.7025</mass>
          <inertia>
            <ixx>0.0171</ixx>
            <ixy>0</ixy>
            <ixz>0</ixz>
            <iyy>0.0163</iyy>
            <iyz>0</iyz>
            <izz>0.006</izz>
          </inertia>
        </inertial>
        <gravity>1</gravity>
        <velocity_decay/>
        <self_collide>0</self_collide>
        <visual name="visual">
          <pose frame="">0 0 1.4 0 0 0</pose>
          <geometry>
            <cylinder>
              <radius>0.04375</radius>
              <length>2.8</length>
            </cylinder>
          </geometry>
          <material>
            <!-- Clark+Kensington Stainless Steel / 37B-4 / #98acc3 Hex Color Code -->
            <diffuse>0.59 0.67 0.76</diffuse>
          </material>
        </visual>
      </link>
      <joint name="joint_4" type="prismatic">
        <parent>link_3</parent>
        <child>link_4</child>
        <axis>
          <xyz>0 0 1</xyz>
          <limit>
            <lower>-1.4</lower>
            <upper>1.4</upper>
            <effort>300</effort>
            <velocity>10</velocity>
          </limit>
          <dynamics>
            <damping>0.0</damping>
            <friction>0</friction>
            <spring_reference>0</spring_reference>
            <spring_stiffness>0</spring_stiffness>
          </dynamics>
          <use_parent_model_frame>1</use_parent_model_frame>
        </axis>
      </joint>
      <!-- Gantry Link 4 (Y-axis "pitch" rotation) -->
      <link name="link_4">
        <pose frame="">0 0 0 0 0 0</pose>
        <inertial>
          <pose frame="">0 0 0 0 0 0</pose>
          <mass>2.7025</mass>
          <inertia>
            <ixx>0.0171</ixx>
            <ixy>0</ixy>
            <ixz>0</ixz>
            <iyy>0.0163</iyy>
            <iyz>0</iyz>
            <izz>0.006</izz>
          </inertia>
        </inertial>
        <gravity>1</gravity>
        <velocity_decay/>
        <self_collide>0</self_collide>
      </link>
      <joint name="joint_5" type="revolute">
        <parent>link_4</parent>
        <child>end_effector</child>
        <axis>
          <xyz>0 -1 0</xyz>
          <limit>
            <lower>-6.28318530718</lower>
            <upper>6.28318530718</upper>
            <effort>300</effort>
            <velocity>10</velocity>
          </limit>
          <dynamics>
            <damping>0.0</damping>
            <friction>0</friction>
            <spring_reference>0</spring_reference>
            <spring_stiffness>0</spring_stiffness>
          </dynamics>
          <use_parent_model_frame>1</use_parent_model_frame>
        </axis>
      </joint>
      <link name="end_effector">
        <pose frame="">0 -0.09375 0 0 0 0</pose>
        <inertial>
          <pose frame="">0.5 0 0 0 0 0</pose>
          <mass>2.7025</mass>
          <inertia>
            <ixx>0.0171</ixx>
            <ixy>0</ixy>
            <ixz>0</ixz>
            <iyy>0.0163</iyy>
            <iyz>0</iyz>
            <izz>0.006</izz>
          </inertia>
        </inertial>
        <visual name="visual">
          <pose frame="">0 0 0 1.5708 0 0</pose>
          <geometry>
            <cylinder>
              <radius>0.125</radius>
              <length>0.07</length>
            </cylinder>
          </geometry>
          <material>
            <!-- Lascaux Carbon black / 181 / #1a3640 Hex Color Code -->
            <diffuse>0.2 0.21 0.25</diffuse>
          </material>
        </visual>
        <visual name="visual_camera">
          <pose frame="">0.15 0 0.1 1.57079632679 0.0 1.57079632679</pose>
          <geometry>
            <mesh>
              <scale>1.0 1.0 1.0</scale>
              <uri>d435.obj</uri>
            </mesh>
          </geometry>
          <material>
            <!-- Lascaux Carbon black / 181 / #1a3640 Hex Color Code -->
            <diffuse>0.2 0.21 0.25</diffuse>
          </material>
        </visual>
        <visual name="visual_camera_stem">
          <pose frame="">0.13 0 0.05 0 0 0</pose>
          <geometry>
            <cylinder>
              <radius>0.01</radius>
              <length>0.1</length>
            </cylinder>
          </geometry>
          <material>
            <!-- Lascaux Carbon black / 181 / #1a3640 Hex Color Code -->
            <diffuse>0.2 0.21 0.25</diffuse>
          </material>
        </visual>
        <!-- call some macros or do other things -->
        <collision name="end_effector_collision_50.0">
          <pose>0.0 -0 0 0 -0 0</pose>
          <geometry>
            <sphere>
              <radius>0.04</radius>
            </sphere>
          </geometry>
        </collision>
        <!-- call some macros or do other things -->
        <collision name="end_effector_collision_49.0">
          <pose>0.02 -0 0 0 -0 0</pose>
          <geometry>
            <sphere>
              <radius>0.0396</radius>
            </sphere>
          </geometry>
        </collision>
        <!-- call some macros or do other things -->
        <collision name="end_effector_collision_48.0">
          <pose>0.04 -0 0 0 -0 0</pose>
          <geometry>
            <sphere>
              <radius>0.0392</radius>
            </sphere>
          </geometry>
        </collision>
        <!-- call some macros or do other things -->
        <collision name="end_effector_collision_47.0">
          <pose>0.06 -0 0 0 -0 0</pose>
          <geometry>
            <sphere>
              <radius>0.0388</radius>
            </sphere>
          </geometry>
        </collision>
        <!-- call some macros or do other things -->
        <collision name="end_effector_collision_46.0">
          <pose>0.08 -0 0 0 -0 0</pose>
          <geometry>
            <sphere>
              <radius>0.0384</radius>
            </sphere>
          </geometry>
        </collision>
        <!-- call some macros or do other things -->
        <collision name="end_effector_collision_45.0">
          <pose>0.1 -0 0 0 -0 0</pose>
          <geometry>
            <sphere>
              <radius>0.038</radius>
            </sphere>
          </geometry>
        </collision>
        <!-- call some macros or do other things -->
        <collision name="end_effector_collision_44.0">
          <pose>0.12 -0 0 0 -0 0</pose>
          <geometry>
            <sphere>
              <radius>0.0376</radius>
            </sphere>
          </geometry>
        </collision>
        <!-- call some macros or do other things -->
        <collision name="end_effector_collision_43.0">
          <pose>0.14 -0 0 0 -0 0</pose>
          <geometry>
            <sphere>
              <radius>0.0372</radius>
            </sphere>
          </geometry>
        </collision>
        <!-- call some macros or do other things -->
        <collision name="end_effector_collision_42.0">
          <pose>0.16 -0 0 0 -0 0</pose>
          <geometry>
            <sphere>
              <radius>0.0368</radius>
            </sphere>
          </geometry>
        </collision>
        <!-- call some macros or do other things -->
        <collision name="end_effector_collision_41.0">
          <pose>0.18 -0 0 0 -0 0</pose>
          <geometry>
            <sphere>
              <radius>0.0364</radius>
            </sphere>
          </geometry>
        </collision>
        <!-- call some macros or do other things -->
        <collision name="end_effector_collision_40.0">
          <pose>0.2 -0 0 0 -0 0</pose>
          <geometry>
            <sphere>
              <radius>0.036</radius>
            </sphere>
          </geometry>
        </collision>
        <!-- call some macros or do other things -->
        <collision name="end_effector_collision_39.0">
          <pose>0.22 -0 0 0 -0 0</pose>
          <geometry>
            <sphere>
              <radius>0.0356</radius>
            </sphere>
          </geometry>
        </collision>
        <!-- call some macros or do other things -->
        <collision name="end_effector_collision_38.0">
          <pose>0.24 -0 0 0 -0 0</pose>
          <geometry>
            <sphere>
              <radius>0.0352</radius>
            </sphere>
          </geometry>
        </collision>
        <!-- call some macros or do other things -->
        <collision name="end_effector_collision_37.0">
          <pose>0.26 -0 0 0 -0 0</pose>
          <geometry>
            <sphere>
              <radius>0.0348</radius>
            </sphere>
          </geometry>
        </collision>
        <!-- call some macros or do other things -->
        <collision name="end_effector_collision_36.0">
          <pose>0.28 -0 0 0 -0 0</pose>
          <geometry>
            <sphere>
              <radius>0.0344</radius>
            </sphere>
          </geometry>
        </collision>
        <!-- call some macros or do other things -->
        <collision name="end_effector_collision_35.0">
          <pose>0.3 -0 0 0 -0 0</pose>
          <geometry>
            <sphere>
              <radius>0.034</radius>
            </sphere>
          </geometry>
        </collision>
        <!-- call some macros or do other things -->
        <collision name="end_effector_collision_34.0">
          <pose>0.32 -0 0 0 -0 0</pose>
          <geometry>
            <sphere>
              <radius>0.0336</radius>
            </sphere>
          </geometry>
        </collision>
        <!-- call some macros or do other things -->
        <collision name="end_effector_collision_33.0">
          <pose>0.34 -0 0 0 -0 0</pose>
          <geometry>
            <sphere>
              <radius>0.0332</radius>
            </sphere>
          </geometry>
        </collision>
        <!-- call some macros or do other things -->
        <collision name="end_effector_collision_32.0">
          <pose>0.36 -0 0 0 -0 0</pose>
          <geometry>
            <sphere>
              <radius>0.0328</radius>
            </sphere>
          </geometry>
        </collision>
        <!-- call some macros or do other things -->
        <collision name="end_effector_collision_31.0">
          <pose>0.38 -0 0 0 -0 0</pose>
          <geometry>
            <sphere>
              <radius>0.0324</radius>
            </sphere>
          </geometry>
        </collision>
        <!-- call some macros or do other things -->
        <collision name="end_effector_collision_30.0">
          <pose>0.4 -0 0 0 -0 0</pose>
          <geometry>
            <sphere>
              <radius>0.032</radius>
            </sphere>
          </geometry>
        </collision>
        <!-- call some macros or do other things -->
        <collision name="end_effector_collision_29.0">
          <pose>0.42 -0 0 0 -0 0</pose>
          <geometry>
            <sphere>
              <radius>0.0316</radius>
            </sphere>
          </geometry>
        </collision>
        <!-- call some macros or do other things -->
        <collision name="end_effector_collision_28.0">
          <pose>0.44 -0 0 0 -0 0</pose>
          <geometry>
            <sphere>
              <radius>0.0312</radius>
            </sphere>
          </geometry>
        </collision>
        <!-- call some macros or do other things -->
        <collision name="end_effector_collision_27.0">
          <pose>0.46 -0 0 0 -0 0</pose>
          <geometry>
            <sphere>
              <radius>0.0308</radius>
            </sphere>
          </geometry>
        </collision>
        <!-- call some macros or do other things -->
        <collision name="end_effector_collision_26.0">
          <pose>0.48 -0 0 0 -0 0</pose>
          <geometry>
            <sphere>
              <radius>0.0304</radius>
            </sphere>
          </geometry>
        </collision>
        <!-- call some macros or do other things -->
        <collision name="end_effector_collision_25.0">
          <pose>0.5 -0 0 0 -0 0</pose>
          <geometry>
            <sphere>
              <radius>0.03</radius>
            </sphere>
          </geometry>
        </collision>
        <!-- call some macros or do other things -->
        <collision name="end_effector_collision_24.0">
          <pose>0.52 -0 0 0 -0 0</pose>
          <geometry>
            <sphere>
              <radius>0.0296</radius>
            </sphere>
          </geometry>
        </collision>
        <!-- call some macros or do other things -->
        <collision name="end_effector_collision_23.0">
          <pose>0.54 -0 0 0 -0 0</pose>
          <geometry>
            <sphere>
              <radius>0.0292</radius>
            </sphere>
          </geometry>
        </collision>
        <!-- call some macros or do other things -->
        <collision name="end_effector_collision_22.0">
          <pose>0.56 -0 0 0 -0 0</pose>
          <geometry>
            <sphere>
              <radius>0.0288</radius>
            </sphere>
          </geometry>
        </collision>
        <!-- call some macros or do other things -->
        <collision name="end_effector_collision_21.0">
          <pose>0.58 -0 0 0 -0 0</pose>
          <geometry>
            <sphere>
              <radius>0.0284</radius>
            </sphere>
          </geometry>
        </collision>
        <!-- call some macros or do other things -->
        <collision name="end_effector_collision_20.0">
          <pose>0.6 -0 0 0 -0 0</pose>
          <geometry>
            <sphere>
              <radius>0.028</radius>
            </sphere>
          </geometry>
        </collision>
        <!-- call some macros or do other things -->
        <collision name="end_effector_collision_19.0">
          <pose>0.62 -0 0 0 -0 0</pose>
          <geometry>
            <sphere>
              <radius>0.0276</radius>
            </sphere>
          </geometry>
        </collision>
        <!-- call some macros or do other things -->
        <collision name="end_effector_collision_18.0">
          <pose>0.64 -0 0 0 -0 0</pose>
          <geometry>
            <sphere>
              <radius>0.0272</radius>
            </sphere>
          </geometry>
        </collision>
        <!-- call some macros or do other things -->
        <collision name="end_effector_collision_17.0">
          <pose>0.66 -0 0 0 -0 0</pose>
          <geometry>
            <sphere>
              <radius>0.0268</radius>
            </sphere>
          </geometry>
        </collision>
        <!-- call some macros or do other things -->
        <collision name="end_effector_collision_16.0">
          <pose>0.68 -0 0 0 -0 0</pose>
          <geometry>
            <sphere>
              <radius>0.0264</radius>
            </sphere>
          </geometry>
        </collision>
        <!-- call some macros or do other things -->
        <collision name="end_effector_collision_15.0">
          <pose>0.7 -0 0 0 -0 0</pose>
          <geometry>
            <sphere>
              <radius>0.026</radius>
            </sphere>
          </geometry>
        </collision>
        <!-- call some macros or do other things -->
        <collision name="end_effector_collision_14.0">
          <pose>0.72 -0 0 0 -0 0</pose>
          <geometry>
            <sphere>
              <radius>0.0256</radius>
            </sphere>
          </geometry>
        </collision>
        <!-- call some macros or do other things -->
        <collision name="end_effector_collision_13.0">
          <pose>0.74 -0 0 0 -0 0</pose>
          <geometry>
            <sphere>
              <radius>0.0252</radius>
            </sphere>
          </geometry>
        </collision>
        <!-- call some macros or do other things -->
        <collision name="end_effector_collision_12.0">
          <pose>0.76 -0 0 0 -0 0</pose>
          <geometry>
            <sphere>
              <radius>0.0248</radius>
            </sphere>
          </geometry>
        </collision>
        <!-- call some macros or do other things -->
        <collision name="end_effector_collision_11.0">
          <pose>0.78 -0 0 0 -0 0</pose>
          <geometry>
            <sphere>
              <radius>0.0244</radius>
            </sphere>
          </geometry>
        </collision>
        <!-- call some macros or do other things -->
        <collision name="end_effector_collision_10.0">
          <pose>0.8 -0 0 0 -0 0</pose>
          <geometry>
            <sphere>
              <radius>0.024</radius>
            </sphere>
          </geometry>
        </collision>
        <!-- call some macros or do other things -->
        <collision name="end_effector_collision_9.0">
          <pose>0.82 -0 0 0 -0 0</pose>
          <geometry>
            <sphere>
              <radius>0.0236</radius>
            </sphere>
          </geometry>
        </collision>
        <!-- call some macros or do other things -->
        <collision name="end_effector_collision_8.0">
          <pose>0.84 -0 0 0 -0 0</pose>
          <geometry>
            <sphere>
              <radius>0.0232</radius>
            </sphere>
          </geometry>
        </collision>
        <!-- call some macros or do other things -->
        <collision name="end_effector_collision_7.0">
          <pose>0.86 -0 0 0 -0 0</pose>
          <geometry>
            <sphere>
              <radius>0.0228</radius>
            </sphere>
          </geometry>
        </collision>
        <!-- call some macros or do other things -->
        <collision name="end_effector_collision_6.0">
          <pose>0.88 -0 0 0 -0 0</pose>
          <geometry>
            <sphere>
              <radius>0.0224</radius>
            </sphere>
          </geometry>
        </collision>
        <!-- call some macros or do other things -->
        <collision name="end_effector_collision_5.0">
          <pose>0.9 -0 0 0 -0 0</pose>
          <geometry>
            <sphere>
              <radius>0.022</radius>
            </sphere>
          </geometry>
        </collision>
        <!-- call some macros or do other things -->
        <collision name="end_effector_collision_4.0">
          <pose>0.92 -0 0 0 -0 0</pose>
          <geometry>
            <sphere>
              <radius>0.0216</radius>
            </sphere>
          </geometry>
        </collision>
        <!-- call some macros or do other things -->
        <collision name="end_effector_collision_3.0">
          <pose>0.94 -0 0 0 -0 0</pose>
          <geometry>
            <sphere>
              <radius>0.0212</radius>
            </sphere>
          </geometry>
        </collision>
        <!-- call some macros or do other things -->
        <collision name="end_effector_collision_2.0">
          <pose>0.96 -0 0 0 -0 0</pose>
          <geometry>
            <sphere>
              <radius>0.0208</radius>
            </sphere>
          </geometry>
        </collision>
        <!-- call some macros or do other things -->
        <collision name="end_effector_collision_1.0">
          <pose>0.98 -0 0 0 -0 0</pose>
          <geometry>
            <sphere>
              <radius>0.0204</radius>
            </sphere>
          </geometry>
        </collision>
        <!-- call some macros or do other things -->
        <collision name="end_effector_collision_0.0">
          <pose>1.0 -0 0 0 -0 0</pose>
          <geometry>
            <sphere>
              <radius>0.02</radius>
            </sphere>
          </geometry>
        </collision>
        <!-- call some macros or do other things -->
        <visual name="end_effector_visual_50.0">
          <pose>0.0 -0 0 0 -0 0</pose>
          <geometry>
            <sphere>
              <radius>0.04</radius>
            </sphere>
          </geometry>
          <material>
            <!-- Lascaux Carbon black / 181 / #1a3640 Hex Color Code -->
            <diffuse>0.2 0.21 0.25</diffuse>
          </material>
        </visual>
        <!-- call some macros or do other things -->
        <visual name="end_effector_visual_49.0">
          <pose>0.02 -0 0 0 -0 0</pose>
          <geometry>
            <sphere>
              <radius>0.0396</radius>
            </sphere>
          </geometry>
          <material>
            <!-- Lascaux Carbon black / 181 / #1a3640 Hex Color Code -->
            <diffuse>0.2 0.21 0.25</diffuse>
          </material>
        </visual>
        <!-- call some macros or do other things -->
        <visual name="end_effector_visual_48.0">
          <pose>0.04 -0 0 0 -0 0</pose>
          <geometry>
            <sphere>
              <radius>0.0392</radius>
            </sphere>
          </geometry>
          <material>
            <!-- Lascaux Carbon black / 181 / #1a3640 Hex Color Code -->
            <diffuse>0.2 0.21 0.25</diffuse>
          </material>
        </visual>
        <!-- call some macros or do other things -->
        <visual name="end_effector_visual_47.0">
          <pose>0.06 -0 0 0 -0 0</pose>
          <geometry>
            <sphere>
              <radius>0.0388</radius>
            </sphere>
          </geometry>
          <material>
            <!-- Lascaux Carbon black / 181 / #1a3640 Hex Color Code -->
            <diffuse>0.2 0.21 0.25</diffuse>
          </material>
        </visual>
        <!-- call some macros or do other things -->
        <visual name="end_effector_visual_46.0">
          <pose>0.08 -0 0 0 -0 0</pose>
          <geometry>
            <sphere>
              <radius>0.0384</radius>
            </sphere>
          </geometry>
          <material>
            <!-- Lascaux Carbon black / 181 / #1a3640 Hex Color Code -->
            <diffuse>0.2 0.21 0.25</diffuse>
          </material>
        </visual>
        <!-- call some macros or do other things -->
        <visual name="end_effector_visual_45.0">
          <pose>0.1 -0 0 0 -0 0</pose>
          <geometry>
            <sphere>
              <radius>0.038</radius>
            </sphere>
          </geometry>
          <material>
            <!-- Lascaux Carbon black / 181 / #1a3640 Hex Color Code -->
            <diffuse>0.2 0.21 0.25</diffuse>
          </material>
        </visual>
        <!-- call some macros or do other things -->
        <visual name="end_effector_visual_44.0">
          <pose>0.12 -0 0 0 -0 0</pose>
          <geometry>
            <sphere>
              <radius>0.0376</radius>
            </sphere>
          </geometry>
          <material>
            <!-- Lascaux Carbon black / 181 / #1a3640 Hex Color Code -->
            <diffuse>0.2 0.21 0.25</diffuse>
          </material>
        </visual>
        <!-- call some macros or do other things -->
        <visual name="end_effector_visual_43.0">
          <pose>0.14 -0 0 0 -0 0</pose>
          <geometry>
            <sphere>
              <radius>0.0372</radius>
            </sphere>
          </geometry>
          <material>
            <!-- Lascaux Carbon black / 181 / #1a3640 Hex Color Code -->
            <diffuse>0.2 0.21 0.25</diffuse>
          </material>
        </visual>
        <!-- call some macros or do other things -->
        <visual name="end_effector_visual_42.0">
          <pose>0.16 -0 0 0 -0 0</pose>
          <geometry>
            <sphere>
              <radius>0.0368</radius>
            </sphere>
          </geometry>
          <material>
            <!-- Lascaux Carbon black / 181 / #1a3640 Hex Color Code -->
            <diffuse>0.2 0.21 0.25</diffuse>
          </material>
        </visual>
        <!-- call some macros or do other things -->
        <visual name="end_effector_visual_41.0">
          <pose>0.18 -0 0 0 -0 0</pose>
          <geometry>
            <sphere>
              <radius>0.0364</radius>
            </sphere>
          </geometry>
          <material>
            <!-- Lascaux Carbon black / 181 / #1a3640 Hex Color Code -->
            <diffuse>0.2 0.21 0.25</diffuse>
          </material>
        </visual>
        <!-- call some macros or do other things -->
        <visual name="end_effector_visual_40.0">
          <pose>0.2 -0 0 0 -0 0</pose>
          <geometry>
            <sphere>
              <radius>0.036</radius>
            </sphere>
          </geometry>
          <material>
            <!-- Lascaux Carbon black / 181 / #1a3640 Hex Color Code -->
            <diffuse>0.2 0.21 0.25</diffuse>
          </material>
        </visual>
        <!-- call some macros or do other things -->
        <visual name="end_effector_visual_39.0">
          <pose>0.22 -0 0 0 -0 0</pose>
          <geometry>
            <sphere>
              <radius>0.0356</radius>
            </sphere>
          </geometry>
          <material>
            <!-- Lascaux Carbon black / 181 / #1a3640 Hex Color Code -->
            <diffuse>0.2 0.21 0.25</diffuse>
          </material>
        </visual>
        <!-- call some macros or do other things -->
        <visual name="end_effector_visual_38.0">
          <pose>0.24 -0 0 0 -0 0</pose>
          <geometry>
            <sphere>
              <radius>0.0352</radius>
            </sphere>
          </geometry>
          <material>
            <!-- Lascaux Carbon black / 181 / #1a3640 Hex Color Code -->
            <diffuse>0.2 0.21 0.25</diffuse>
          </material>
        </visual>
        <!-- call some macros or do other things -->
        <visual name="end_effector_visual_37.0">
          <pose>0.26 -0 0 0 -0 0</pose>
          <geometry>
            <sphere>
              <radius>0.0348</radius>
            </sphere>
          </geometry>
          <material>
            <!-- Lascaux Carbon black / 181 / #1a3640 Hex Color Code -->
            <diffuse>0.2 0.21 0.25</diffuse>
          </material>
        </visual>
        <!-- call some macros or do other things -->
        <visual name="end_effector_visual_36.0">
          <pose>0.28 -0 0 0 -0 0</pose>
          <geometry>
            <sphere>
              <radius>0.0344</radius>
            </sphere>
          </geometry>
          <material>
            <!-- Lascaux Carbon black / 181 / #1a3640 Hex Color Code -->
            <diffuse>0.2 0.21 0.25</diffuse>
          </material>
        </visual>
        <!-- call some macros or do other things -->
        <visual name="end_effector_visual_35.0">
          <pose>0.3 -0 0 0 -0 0</pose>
          <geometry>
            <sphere>
              <radius>0.034</radius>
            </sphere>
          </geometry>
          <material>
            <!-- Lascaux Carbon black / 181 / #1a3640 Hex Color Code -->
            <diffuse>0.2 0.21 0.25</diffuse>
          </material>
        </visual>
        <!-- call some macros or do other things -->
        <visual name="end_effector_visual_34.0">
          <pose>0.32 -0 0 0 -0 0</pose>
          <geometry>
            <sphere>
              <radius>0.0336</radius>
            </sphere>
          </geometry>
          <material>
            <!-- Lascaux Carbon black / 181 / #1a3640 Hex Color Code -->
            <diffuse>0.2 0.21 0.25</diffuse>
          </material>
        </visual>
        <!-- call some macros or do other things -->
        <visual name="end_effector_visual_33.0">
          <pose>0.34 -0 0 0 -0 0</pose>
          <geometry>
            <sphere>
              <radius>0.0332</radius>
            </sphere>
          </geometry>
          <material>
            <!-- Lascaux Carbon black / 181 / #1a3640 Hex Color Code -->
            <diffuse>0.2 0.21 0.25</diffuse>
          </material>
        </visual>
        <!-- call some macros or do other things -->
        <visual name="end_effector_visual_32.0">
          <pose>0.36 -0 0 0 -0 0</pose>
          <geometry>
            <sphere>
              <radius>0.0328</radius>
            </sphere>
          </geometry>
          <material>
            <!-- Lascaux Carbon black / 181 / #1a3640 Hex Color Code -->
            <diffuse>0.2 0.21 0.25</diffuse>
          </material>
        </visual>
        <!-- call some macros or do other things -->
        <visual name="end_effector_visual_31.0">
          <pose>0.38 -0 0 0 -0 0</pose>
          <geometry>
            <sphere>
              <radius>0.0324</radius>
            </sphere>
          </geometry>
          <material>
            <!-- Lascaux Carbon black / 181 / #1a3640 Hex Color Code -->
            <diffuse>0.2 0.21 0.25</diffuse>
          </material>
        </visual>
        <!-- call some macros or do other things -->
        <visual name="end_effector_visual_30.0">
          <pose>0.4 -0 0 0 -0 0</pose>
          <geometry>
            <sphere>
              <radius>0.032</radius>
            </sphere>
          </geometry>
          <material>
            <!-- Lascaux Carbon black / 181 / #1a3640 Hex Color Code -->
            <diffuse>0.2 0.21 0.25</diffuse>
          </material>
        </visual>
        <!-- call some macros or do other things -->
        <visual name="end_effector_visual_29.0">
          <pose>0.42 -0 0 0 -0 0</pose>
          <geometry>
            <sphere>
              <radius>0.0316</radius>
            </sphere>
          </geometry>
          <material>
            <!-- Lascaux Carbon black / 181 / #1a3640 Hex Color Code -->
            <diffuse>0.2 0.21 0.25</diffuse>
          </material>
        </visual>
        <!-- call some macros or do other things -->
        <visual name="end_effector_visual_28.0">
          <pose>0.44 -0 0 0 -0 0</pose>
          <geometry>
            <sphere>
              <radius>0.0312</radius>
            </sphere>
          </geometry>
          <material>
            <!-- Lascaux Carbon black / 181 / #1a3640 Hex Color Code -->
            <diffuse>0.2 0.21 0.25</diffuse>
          </material>
        </visual>
        <!-- call some macros or do other things -->
        <visual name="end_effector_visual_27.0">
          <pose>0.46 -0 0 0 -0 0</pose>
          <geometry>
            <sphere>
              <radius>0.0308</radius>
            </sphere>
          </geometry>
          <material>
            <!-- Lascaux Carbon black / 181 / #1a3640 Hex Color Code -->
            <diffuse>0.2 0.21 0.25</diffuse>
          </material>
        </visual>
        <!-- call some macros or do other things -->
        <visual name="end_effector_visual_26.0">
          <pose>0.48 -0 0 0 -0 0</pose>
          <geometry>
            <sphere>
              <radius>0.0304</radius>
            </sphere>
          </geometry>
          <material>
            <!-- Lascaux Carbon black / 181 / #1a3640 Hex Color Code -->
            <diffuse>0.2 0.21 0.25</diffuse>
          </material>
        </visual>
        <!-- call some macros or do other things -->
        <visual name="end_effector_visual_25.0">
          <pose>0.5 -0 0 0 -0 0</pose>
          <geometry>
            <sphere>
              <radius>0.03</radius>
            </sphere>
          </geometry>
          <material>
            <!-- Lascaux Carbon black / 181 / #1a3640 Hex Color Code -->
            <diffuse>0.2 0.21 0.25</diffuse>
          </material>
        </visual>
        <!-- call some macros or do other things -->
        <visual name="end_effector_visual_24.0">
          <pose>0.52 -0 0 0 -0 0</pose>
          <geometry>
            <sphere>
              <radius>0.0296</radius>
            </sphere>
          </geometry>
          <material>
            <!-- Lascaux Carbon black / 181 / #1a3640 Hex Color Code -->
            <diffuse>0.2 0.21 0.25</diffuse>
          </material>
        </visual>
        <!-- call some macros or do other things -->
        <visual name="end_effector_visual_23.0">
          <pose>0.54 -0 0 0 -0 0</pose>
          <geometry>
            <sphere>
              <radius>0.0292</radius>
            </sphere>
          </geometry>
          <material>
            <!-- Lascaux Carbon black / 181 / #1a3640 Hex Color Code -->
            <diffuse>0.2 0.21 0.25</diffuse>
          </material>
        </visual>
        <!-- call some macros or do other things -->
        <visual name="end_effector_visual_22.0">
          <pose>0.56 -0 0 0 -0 0</pose>
          <geometry>
            <sphere>
              <radius>0.0288</radius>
            </sphere>
          </geometry>
          <material>
            <!-- Lascaux Carbon black / 181 / #1a3640 Hex Color Code -->
            <diffuse>0.2 0.21 0.25</diffuse>
          </material>
        </visual>
        <!-- call some macros or do other things -->
        <visual name="end_effector_visual_21.0">
          <pose>0.58 -0 0 0 -0 0</pose>
          <geometry>
            <sphere>
              <radius>0.0284</radius>
            </sphere>
          </geometry>
          <material>
            <!-- Lascaux Carbon black / 181 / #1a3640 Hex Color Code -->
            <diffuse>0.2 0.21 0.25</diffuse>
          </material>
        </visual>
        <!-- call some macros or do other things -->
        <visual name="end_effector_visual_20.0">
          <pose>0.6 -0 0 0 -0 0</pose>
          <geometry>
            <sphere>
              <radius>0.028</radius>
            </sphere>
          </geometry>
          <material>
            <!-- Lascaux Carbon black / 181 / #1a3640 Hex Color Code -->
            <diffuse>0.2 0.21 0.25</diffuse>
          </material>
        </visual>
        <!-- call some macros or do other things -->
        <visual name="end_effector_visual_19.0">
          <pose>0.62 -0 0 0 -0 0</pose>
          <geometry>
            <sphere>
              <radius>0.0276</radius>
            </sphere>
          </geometry>
          <material>
            <!-- Lascaux Carbon black / 181 / #1a3640 Hex Color Code -->
            <diffuse>0.2 0.21 0.25</diffuse>
          </material>
        </visual>
        <!-- call some macros or do other things -->
        <visual name="end_effector_visual_18.0">
          <pose>0.64 -0 0 0 -0 0</pose>
          <geometry>
            <sphere>
              <radius>0.0272</radius>
            </sphere>
          </geometry>
          <material>
            <!-- Lascaux Carbon black / 181 / #1a3640 Hex Color Code -->
            <diffuse>0.2 0.21 0.25</diffuse>
          </material>
        </visual>
        <!-- call some macros or do other things -->
        <visual name="end_effector_visual_17.0">
          <pose>0.66 -0 0 0 -0 0</pose>
          <geometry>
            <sphere>
              <radius>0.0268</radius>
            </sphere>
          </geometry>
          <material>
            <!-- Lascaux Carbon black / 181 / #1a3640 Hex Color Code -->
            <diffuse>0.2 0.21 0.25</diffuse>
          </material>
        </visual>
        <!-- call some macros or do other things -->
        <visual name="end_effector_visual_16.0">
          <pose>0.68 -0 0 0 -0 0</pose>
          <geometry>
            <sphere>
              <radius>0.0264</radius>
            </sphere>
          </geometry>
          <material>
            <!-- Lascaux Carbon black / 181 / #1a3640 Hex Color Code -->
            <diffuse>0.2 0.21 0.25</diffuse>
          </material>
        </visual>
        <!-- call some macros or do other things -->
        <visual name="end_effector_visual_15.0">
          <pose>0.7 -0 0 0 -0 0</pose>
          <geometry>
            <sphere>
              <radius>0.026</radius>
            </sphere>
          </geometry>
          <material>
            <!-- Lascaux Carbon black / 181 / #1a3640 Hex Color Code -->
            <diffuse>0.2 0.21 0.25</diffuse>
          </material>
        </visual>
        <!-- call some macros or do other things -->
        <visual name="end_effector_visual_14.0">
          <pose>0.72 -0 0 0 -0 0</pose>
          <geometry>
            <sphere>
              <radius>0.0256</radius>
            </sphere>
          </geometry>
          <material>
            <!-- Lascaux Carbon black / 181 / #1a3640 Hex Color Code -->
            <diffuse>0.2 0.21 0.25</diffuse>
          </material>
        </visual>
        <!-- call some macros or do other things -->
        <visual name="end_effector_visual_13.0">
          <pose>0.74 -0 0 0 -0 0</pose>
          <geometry>
            <sphere>
              <radius>0.0252</radius>
            </sphere>
          </geometry>
          <material>
            <!-- Lascaux Carbon black / 181 / #1a3640 Hex Color Code -->
            <diffuse>0.2 0.21 0.25</diffuse>
          </material>
        </visual>
        <!-- call some macros or do other things -->
        <visual name="end_effector_visual_12.0">
          <pose>0.76 -0 0 0 -0 0</pose>
          <geometry>
            <sphere>
              <radius>0.0248</radius>
            </sphere>
          </geometry>
          <material>
            <!-- Lascaux Carbon black / 181 / #1a3640 Hex Color Code -->
            <diffuse>0.2 0.21 0.25</diffuse>
          </material>
        </visual>
        <!-- call some macros or do other things -->
        <visual name="end_effector_visual_11.0">
          <pose>0.78 -0 0 0 -0 0</pose>
          <geometry>
            <sphere>
              <radius>0.0244</radius>
            </sphere>
          </geometry>
          <material>
            <!-- Lascaux Carbon black / 181 / #1a3640 Hex Color Code -->
            <diffuse>0.2 0.21 0.25</diffuse>
          </material>
        </visual>
        <!-- call some macros or do other things -->
        <visual name="end_effector_visual_10.0">
          <pose>0.8 -0 0 0 -0 0</pose>
          <geometry>
            <sphere>
              <radius>0.024</radius>
            </sphere>
          </geometry>
          <material>
            <!-- Lascaux Carbon black / 181 / #1a3640 Hex Color Code -->
            <diffuse>0.2 0.21 0.25</diffuse>
          </material>
        </visual>
        <!-- call some macros or do other things -->
        <visual name="end_effector_visual_9.0">
          <pose>0.82 -0 0 0 -0 0</pose>
          <geometry>
            <sphere>
              <radius>0.0236</radius>
            </sphere>
          </geometry>
          <material>
            <!-- Lascaux Carbon black / 181 / #1a3640 Hex Color Code -->
            <diffuse>0.2 0.21 0.25</diffuse>
          </material>
        </visual>
        <!-- call some macros or do other things -->
        <visual name="end_effector_visual_8.0">
          <pose>0.84 -0 0 0 -0 0</pose>
          <geometry>
            <sphere>
              <radius>0.0232</radius>
            </sphere>
          </geometry>
          <material>
            <!-- Lascaux Carbon black / 181 / #1a3640 Hex Color Code -->
            <diffuse>0.2 0.21 0.25</diffuse>
          </material>
        </visual>
        <!-- call some macros or do other things -->
        <visual name="end_effector_visual_7.0">
          <pose>0.86 -0 0 0 -0 0</pose>
          <geometry>
            <sphere>
              <radius>0.0228</radius>
            </sphere>
          </geometry>
          <material>
            <!-- Lascaux Carbon black / 181 / #1a3640 Hex Color Code -->
            <diffuse>0.2 0.21 0.25</diffuse>
          </material>
        </visual>
        <!-- call some macros or do other things -->
        <visual name="end_effector_visual_6.0">
          <pose>0.88 -0 0 0 -0 0</pose>
          <geometry>
            <sphere>
              <radius>0.0224</radius>
            </sphere>
          </geometry>
          <material>
            <!-- Lascaux Carbon black / 181 / #1a3640 Hex Color Code -->
            <diffuse>0.2 0.21 0.25</diffuse>
          </material>
        </visual>
        <!-- call some macros or do other things -->
        <visual name="end_effector_visual_5.0">
          <pose>0.9 -0 0 0 -0 0</pose>
          <geometry>
            <sphere>
              <radius>0.022</radius>
            </sphere>
          </geometry>
          <material>
            <!-- Lascaux Carbon black / 181 / #1a3640 Hex Color Code -->
            <diffuse>0.2 0.21 0.25</diffuse>
          </material>
        </visual>
        <!-- call some macros or do other things -->
        <visual name="end_effector_visual_4.0">
          <pose>0.92 -0 0 0 -0 0</pose>
          <geometry>
            <sphere>
              <radius>0.0216</radius>
            </sphere>
          </geometry>
          <material>
            <!-- Lascaux Carbon black / 181 / #1a3640 Hex Color Code -->
            <diffuse>0.2 0.21 0.25</diffuse>
          </material>
        </visual>
        <!-- call some macros or do other things -->
        <visual name="end_effector_visual_3.0">
          <pose>0.94 -0 0 0 -0 0</pose>
          <geometry>
            <sphere>
              <radius>0.0212</radius>
            </sphere>
          </geometry>
          <material>
            <!-- Lascaux Carbon black / 181 / #1a3640 Hex Color Code -->
            <diffuse>0.2 0.21 0.25</diffuse>
          </material>
        </visual>
        <!-- call some macros or do other things -->
        <visual name="end_effector_visual_2.0">
          <pose>0.96 -0 0 0 -0 0</pose>
          <geometry>
            <sphere>
              <radius>0.0208</radius>
            </sphere>
          </geometry>
          <material>
            <!-- Lascaux Carbon black / 181 / #1a3640 Hex Color Code -->
            <diffuse>0.2 0.21 0.25</diffuse>
          </material>
        </visual>
        <!-- call some macros or do other things -->
        <visual name="end_effector_visual_1.0">
          <pose>0.98 -0 0 0 -0 0</pose>
          <geometry>
            <sphere>
              <radius>0.0204</radius>
            </sphere>
          </geometry>
          <material>
            <!-- Lascaux Carbon black / 181 / #1a3640 Hex Color Code -->
            <diffuse>0.2 0.21 0.25</diffuse>
          </material>
        </visual>
        <!-- call some macros or do other things -->
        <visual name="end_effector_visual_0.0">
          <pose>1.0 -0 0 0 -0 0</pose>
          <geometry>
            <sphere>
              <radius>0.02</radius>
            </sphere>
          </geometry>
          <material>
            <!-- Lascaux Carbon black / 181 / #1a3640 Hex Color Code -->
            <diffuse>0.2 0.21 0.25</diffuse>
          </material>
        </visual>
        <gravity>1</gravity>
        <velocity_decay/>
      </link>
    </model>
  </sdf>

